<?xml version="1.0" encoding="utf-8"?>
<robot name="left_robotic_arm_hand">

  <!-- ======================= -->
  <!-- ====   MATERIALS   ==== -->
  <!-- ======================= -->
  <material name="dark_grey"><color rgba="0.2 0.2 0.2 1.0"/></material>
  <material name="light_grey"><color rgba="0.8 0.8 0.8 1.0"/></material>
  <material name="yellow"><color rgba="1.0 0.85 0.1 1.0"/></material>
  <material name="red"><color rgba="0.9 0.2 0.2 1.0"/></material>

  <!-- ======================= -->
  <!-- ====   BASE & ARM  ==== -->
  <!-- ======================= -->
  
  <link name="base_link">
    <visual>
      <origin xyz="0.0 0.0 0.0" rpy="0.0 0.0 0.0"/>
      <geometry><box size="0.1 0.1 0.01"/></geometry>
      <material name="dark_grey"/>
    </visual>
    <visual>
      <origin xyz="0.0 0.0 0.25" rpy="0.0 0.0 0.0"/>
      <geometry><cylinder length="0.5" radius="0.01"/></geometry>
      <material name="dark_grey"/>
    </visual>
    <visual>
      <origin xyz="0.0 0.0 0.5" rpy="0.0 0.0 0.0"/>
      <geometry><sphere radius="0.03"/></geometry>
      <material name="yellow"/>
    </visual>
  </link>

  <joint name="shoulder_pan_joint" type="revolute">
    <parent link="base_link"/>
    <child link="shoulder_pan_link"/>
    <origin xyz="0 0 0.5" rpy="0 0 0"/>
    <axis xyz="0 0 1"/>
    <limit lower="-1.57" upper="1.57" effort="100" velocity="1.0"/>
  </joint>
  <link name="shoulder_pan_link"/>

  <joint name="shoulder_tilt_joint" type="revolute">
    <parent link="shoulder_pan_link"/>
    <child link="upper_arm_link"/>
    <origin xyz="0 0 0" rpy="0 0 0"/>
    <axis xyz="0 1 0"/>
    <limit lower="-1.57" upper="0.94" effort="100" velocity="1.0"/>
  </joint>
  <link name="upper_arm_link">
    <visual>
        <geometry><cylinder length="0.2" radius="0.02"/></geometry>
        <origin xyz="0.1 0 0" rpy="0 1.57 0"/>
        <material name="light_grey"/>
    </visual>
    <visual>
        <geometry><sphere radius="0.02"/></geometry>
        <origin xyz="0.2 0 0" rpy="0 0 0"/>
        <material name="yellow"/>
    </visual>    
  </link>

  <joint name="elbow_flex_joint" type="revolute">
    <parent link="upper_arm_link"/>
    <child link="elbow_rot_link"/>
    <origin xyz="0.22 0 0" rpy="0 0 0"/>
    <axis xyz="0 -1 0"/>
    <limit lower="0" upper="2.6" effort="100" velocity="1.0"/>
  </joint>
  <link name="elbow_rot_link"/>

  <joint name="elbow_rot_joint" type="revolute">
    <parent link="elbow_rot_link"/>
    <child link="forearm_link"/>
    <origin xyz="0 0 0" rpy="0 0 0"/>
    <axis xyz="1 0 0"/>
    <limit lower="-1.57" upper="1.57" effort="50" velocity="1.5"/>
  </joint>
  <link name="forearm_link">
    <visual>
        <geometry><cylinder length="0.18" radius="0.02"/></geometry>
        <origin xyz="0.09 0 0" rpy="0 1.57 0"/>
        <material name="light_grey"/>
    </visual>
    <visual>
        <geometry><sphere radius="0.02"/></geometry>
        <origin xyz="0.18 0 0" rpy="0 0 0"/>
        <material name="yellow"/>
    </visual>    
  </link>

  <!-- WRIST FLEXION (Up/Down) -->
  <joint name="wrist_flex_joint" type="revolute">
    <parent link="forearm_link"/>
    <child link="wrist_abd_link"/>
    <origin xyz="0.19 0 0" rpy="0 0 0"/>
    <axis xyz="0 1 0"/>
    <limit lower="1.57" upper="4.71" effort="30" velocity="1.0"/>
  </joint>
  <link name="wrist_abd_link"/>

  <!-- WRIST ABDUCTION / PALM ATTACHMENT -->
  <joint name="wrist_abd_joint" type="revolute">
    <parent link="wrist_abd_link"/>
    <child link="palm_link"/>
    <origin xyz="0 0 0" rpy="0 -1.5708 0"/> 
    <axis xyz="0 0 1"/>
    <limit lower="-2.0" upper="2.0" effort="30" velocity="1.0"/>
  </joint>

  <!-- ======================= -->
  <!-- ====      PALM     ==== -->
  <!-- ======================= -->
  <link name="palm_link">
    <inertial>
      <origin xyz="-0.00292 -0.00042 0.03649" rpy="0 0 0" />
      <mass value="0.2179" />
      <inertia ixx="0.000185" ixy="-6.9e-07" ixz="6.8e-06" iyy="0.000122" iyz="1.2e-05" izz="8.3e-05" />
    </inertial>
    <visual>
      <origin xyz="0 0 0" rpy="0 0 0" />
      <geometry><mesh filename="package://arm/meshes/left/palm_link.STL" /></geometry>
      <material name="light_grey"/>
    </visual>
    <collision>
      <geometry><mesh filename="package://arm/meshes/left/palm_link.STL" /></geometry>
    </collision>
  </link>

  <!-- ======================= -->
  <!-- ====   FINGER 1    ==== -->
  <!-- ======================= -->
  <link name="finger1_link1"><visual><geometry><mesh filename="package://arm/meshes/left/finger1_link1.STL"/></geometry></visual></link>
  <joint name="finger1_joint1" type="revolute">
    <origin xyz="0.0085244 -0.020575 0.028712" rpy="1.328 -0.37161 0.7307" />
    <parent link="palm_link" /><child link="finger1_link1" />
    <axis xyz="0 1 0" /><limit lower="-0.0448" upper="1.6508" effort="0.6" velocity="8.58" />
  </joint>
  <link name="finger1_link2"><visual><geometry><mesh filename="package://arm/meshes/left/finger1_link2.STL"/></geometry></visual></link>
  <joint name="finger1_joint2" type="revolute">
    <origin xyz="-0.0047549 0.0060191 0.014132" rpy="-0.27968 -0.55633 -0.081982" />
    <parent link="finger1_link1" /><child link="finger1_link2" />
    <axis xyz="-1 0 0" /><limit lower="-0.1659" upper="0.9339" effort="0.6" velocity="11.1" />
  </joint>
  <link name="finger1_link3"><visual><geometry><mesh filename="package://arm/meshes/left/finger1_link3.STL"/></geometry></visual></link>
  <joint name="finger1_joint3" type="revolute">
    <origin xyz="0.0009915 -0.00026671 0.033166" rpy="-0.049049 0.017311 0.33774" />
    <parent link="finger1_link2" /><child link="finger1_link3" />
    <axis xyz="0 1 0" /><limit lower="-0.4932" upper="1.6272" effort="0.3" velocity="12.86" />
  </joint>
  <link name="finger1_link4"><visual><geometry><mesh filename="package://arm/meshes/left/finger1_link4.STL"/></geometry></visual></link>
  <joint name="finger1_joint4" type="revolute">
    <origin xyz="0 4.0225E-05 0.028987" rpy="0 0 0" />
    <parent link="finger1_link3" /><child link="finger1_link4" />
    <axis xyz="0 1 0" /><limit lower="-0.4932" upper="1.6272" effort="0.3" velocity="13.57" />
  </joint>
  <link name="finger1_tip_link"><visual><geometry><mesh filename="package://arm/meshes/left/finger1_tip_link.STL"/></geometry></visual></link>
  <joint name="finger1_tip_fixed" type="fixed">
    <origin xyz="-0.001058 -0.00044022 0.029313" rpy="0 0 0" /><parent link="finger1_link4" /><child link="finger1_tip_link" />
  </joint>

  <!-- ======================= -->
  <!-- ====   FINGER 2    ==== -->
  <!-- ======================= -->
  <link name="finger2_link1"><visual><geometry><mesh filename="package://arm/meshes/left/finger2_link1.STL"/></geometry></visual></link>
  <joint name="finger2_joint1" type="revolute">
    <origin xyz="-0.0058701 -0.029434 0.091917" rpy="0.11071 -0.071133 0.21823" />
    <parent link="palm_link" /><child link="finger2_link1" />
    <axis xyz="0 1 0" /><limit lower="-0.32695" upper="1.63595" effort="1" velocity="8.2" />
  </joint>
  <link name="finger2_link2"><visual><geometry><mesh filename="package://arm/meshes/left/finger2_link2.STL"/></geometry></visual></link>
  <joint name="finger2_joint2" type="revolute">
    <origin xyz="0.0022 0 0.004" rpy="-0.00043322 1.0969E-05 0" />
    <parent link="finger2_link1" /><child link="finger2_link2" />
    <axis xyz="-1 0 0" /><limit lower="-0.495" upper="0.495" effort="0.2" velocity="8.11" />
  </joint>
  <link name="finger2_link3"><visual><geometry><mesh filename="package://arm/meshes/left/finger2_link3.STL"/></geometry></visual></link>
  <joint name="finger2_joint3" type="revolute">
    <origin xyz="-0.0046 0 0.036618" rpy="0 0 -0.00026861" />
    <parent link="finger2_link2" /><child link="finger2_link3" />
    <axis xyz="0 1 0" /><limit lower="-0.4932" upper="1.6272" effort="0.3" velocity="12.86" />
  </joint>
  <link name="finger2_link4"><visual><geometry><mesh filename="package://arm/meshes/left/finger2_link4.STL"/></geometry></visual></link>
  <joint name="finger2_joint4" type="revolute">
    <origin xyz="0 0 0.029" rpy="0 0 0" />
    <parent link="finger2_link3" /><child link="finger2_link4" />
    <axis xyz="0 1 0" /><limit lower="-0.4932" upper="1.6272" effort="0.3" velocity="13.57" />
  </joint>
  <link name="finger2_tip_link"><visual><geometry><mesh filename="package://arm/meshes/left/finger2_tip_link.STL"/></geometry></visual></link>
  <joint name="finger2_tip_fixed" type="fixed">
    <origin xyz="-0.0010404 0 0.0267" rpy="0 0 0" /><parent link="finger2_link4" /><child link="finger2_tip_link" />
  </joint>

  <!-- ======================= -->
  <!-- ====   FINGER 3    ==== -->
  <!-- ======================= -->
  <link name="finger3_link1"><visual><geometry><mesh filename="package://arm/meshes/left/finger3_link1.STL"/></geometry></visual></link>
  <joint name="finger3_joint1" type="revolute">
    <origin xyz="-0.01046 -0.0074615 0.089544" rpy="5.0886E-05 -0.087266 -0.00058387" />
    <parent link="palm_link" /><child link="finger3_link1" />
    <axis xyz="0 1 0" /><limit lower="-0.32695" upper="1.63595" effort="1" velocity="8.2" />
  </joint>
  <link name="finger3_link2"><visual><geometry><mesh filename="package://arm/meshes/left/finger3_link2.STL"/></geometry></visual></link>
  <joint name="finger3_joint2" type="revolute">
    <origin xyz="0.0022 0 0.004" rpy="-0.00043323 0 0" />
    <parent link="finger3_link1" /><child link="finger3_link2" />
    <axis xyz="-1 0 0" /><limit lower="-0.495" upper="0.495" effort="0.2" velocity="8.11" />
  </joint>
  <link name="finger3_link3"><visual><geometry><mesh filename="package://arm/meshes/left/finger3_link3.STL"/></geometry></visual></link>
  <joint name="finger3_joint3" type="revolute">
    <origin xyz="-0.0046 0 0.036618" rpy="0 0 -0.00026862" />
    <parent link="finger3_link2" /><child link="finger3_link3" />
    <axis xyz="0 1 0" /><limit lower="-0.4932" upper="1.6272" effort="0.3" velocity="12.86" />
  </joint>
  <link name="finger3_link4"><visual><geometry><mesh filename="package://arm/meshes/left/finger3_link4.STL"/></geometry></visual></link>
  <joint name="finger3_joint4" type="revolute">
    <origin xyz="0 0 0.029" rpy="0 0 0" />
    <parent link="finger3_link3" /><child link="finger3_link4" />
    <axis xyz="0 1 0" /><limit lower="-0.4932" upper="1.6272" effort="0.3" velocity="13.57" />
  </joint>
  <link name="finger3_tip_link"><visual><geometry><mesh filename="package://arm/meshes/left/finger3_tip_link.STL"/></geometry></visual></link>
  <joint name="finger3_tip_fixed" type="fixed">
    <origin xyz="-0.0010404 0 0.0267" rpy="0 0 0" /><parent link="finger3_link4" /><child link="finger3_tip_link" />
  </joint>

  <!-- ======================= -->
  <!-- ====   FINGER 4    ==== -->
  <!-- ======================= -->
  <link name="finger4_link1"><visual><geometry><mesh filename="package://arm/meshes/left/finger4_link1.STL"/></geometry></visual></link>
  <joint name="finger4_joint1" type="revolute">
    <origin xyz="-0.0076649 0.013712 0.084429" rpy="-0.090379 -0.084038 -0.047072" />
    <parent link="palm_link" /><child link="finger4_link1" />
    <axis xyz="0 1 0" /><limit lower="-0.32695" upper="1.63595" effort="1" velocity="8.2" />
  </joint>
  <link name="finger4_link2"><visual><geometry><mesh filename="package://arm/meshes/left/finger4_link2.STL"/></geometry></visual></link>
  <joint name="finger4_joint2" type="revolute">
    <origin xyz="0.0022024 0 0.0039987" rpy="-0.00043323 0.00060486 0" />
    <parent link="finger4_link1" /><child link="finger4_link2" />
    <axis xyz="-1 0 0" /><limit lower="-0.495" upper="0.495" effort="0.2" velocity="8.11" />
  </joint>
  <link name="finger4_link3"><visual><geometry><mesh filename="package://arm/meshes/left/finger4_link3.STL"/></geometry></visual></link>
  <joint name="finger4_joint3" type="revolute">
    <origin xyz="-0.0046 0 0.036618" rpy="0 0 -0.00026862" />
    <parent link="finger4_link2" /><child link="finger4_link3" />
    <axis xyz="0 1 0" /><limit lower="-0.4932" upper="1.6272" effort="0.3" velocity="12.86" />
  </joint>
  <link name="finger4_link4"><visual><geometry><mesh filename="package://arm/meshes/left/finger4_link4.STL"/></geometry></visual></link>
  <joint name="finger4_joint4" type="revolute">
    <origin xyz="0 0 0.029" rpy="0 0 0" />
    <parent link="finger4_link3" /><child link="finger4_link4" />
    <axis xyz="0 1 0" /><limit lower="-0.4932" upper="1.6272" effort="0.3" velocity="13.57" />
  </joint>
  <link name="finger4_tip_link"><visual><geometry><mesh filename="package://arm/meshes/left/finger4_tip_link.STL"/></geometry></visual></link>
  <joint name="finger4_tip_fixed" type="fixed">
    <origin xyz="-0.0010993 0 0.026698" rpy="0 0 0" /><parent link="finger4_link4" /><child link="finger4_tip_link" />
  </joint>

  <!-- ======================= -->
  <!-- ====   FINGER 5    ==== -->
  <!-- ======================= -->
  <link name="finger5_link1"><visual><geometry><mesh filename="package://arm/meshes/left/finger5_link1.STL"/></geometry></visual></link>
  <joint name="finger5_joint1" type="revolute">
    <origin xyz="-0.0022687 0.034001 0.074281" rpy="-0.1925 -0.09326 -0.15753" />
    <parent link="palm_link" /><child link="finger5_link1" />
    <axis xyz="0 1 0" /><limit lower="-0.32695" upper="1.63595" effort="1" velocity="8.2" />
  </joint>
  <link name="finger5_link2"><visual><geometry><mesh filename="package://arm/meshes/left/finger5_link2.STL"/></geometry></visual></link>
  <joint name="finger5_joint2" type="revolute">
    <origin xyz="0.002203 0 0.0039983" rpy="-0.00043323 0.00075655 0" />
    <parent link="finger5_link1" /><child link="finger5_link2" />
    <axis xyz="-1 0 0" /><limit lower="-0.495" upper="0.495" effort="0.2" velocity="8.11" />
  </joint>
  <link name="finger5_link3"><visual><geometry><mesh filename="package://arm/meshes/left/finger5_link3.STL"/></geometry></visual></link>
  <joint name="finger5_joint3" type="revolute">
    <origin xyz="-0.0046 0 0.036618" rpy="0 0 -0.00026862" />
    <parent link="finger5_link2" /><child link="finger5_link3" />
    <axis xyz="0 1 0" /><limit lower="-0.4932" upper="1.6272" effort="0.3" velocity="12.86" />
  </joint>
  <link name="finger5_link4"><visual><geometry><mesh filename="package://arm/meshes/left/finger5_link4.STL"/></geometry></visual></link>
  <joint name="finger5_joint4" type="revolute">
    <origin xyz="0 0 0.029" rpy="0 0 0" />
    <parent link="finger5_link3" /><child link="finger5_link4" />
    <axis xyz="0 1 0" /><limit lower="-0.4932" upper="1.6272" effort="0.3" velocity="13.57" />
  </joint>
  <link name="finger5_tip_link"><visual><geometry><mesh filename="package://arm/meshes/left/finger5_tip_link.STL"/></geometry></visual></link>
  <joint name="finger5_tip_fixed" type="fixed">
    <origin xyz="-0.0011127 0 0.026697" rpy="0 0 0" /><parent link="finger5_link4" /><child link="finger5_tip_link" />
  </joint>

</robot>